RemoteConnectionError occurred at Sun Feb  4 11:18:21 2024 with params={'content-type': 'application/json', 'path': '/VariantValidator/variantvalidator/GRCh37/NM_000088.3:c.589G>T/NM_000093.4'}
Traceback (most recent call last):
  File "/usr/local/miniconda3/envs/vValidator/lib/python3.12/site-packages/urllib3/connection.py", line 203, in _new_conn
    sock = connection.create_connection(
           ^^^^^^^^^^^^^^^^^^^^^^^^^^^^^
  File "/usr/local/miniconda3/envs/vValidator/lib/python3.12/site-packages/urllib3/util/connection.py", line 60, in create_connection
    for res in socket.getaddrinfo(host, port, family, socket.SOCK_STREAM):
               ^^^^^^^^^^^^^^^^^^^^^^^^^^^^^^^^^^^^^^^^^^^^^^^^^^^^^^^^^^
  File "/usr/local/miniconda3/envs/vValidator/lib/python3.12/socket.py", line 963, in getaddrinfo
    for res in _socket.getaddrinfo(host, port, family, type, proto, flags):
               ^^^^^^^^^^^^^^^^^^^^^^^^^^^^^^^^^^^^^^^^^^^^^^^^^^^^^^^^^^^
socket.gaierror: [Errno -3] Temporary failure in name resolution

The above exception was the direct cause of the following exception:

Traceback (most recent call last):
  File "/usr/local/miniconda3/envs/vValidator/lib/python3.12/site-packages/urllib3/connectionpool.py", line 790, in urlopen
    response = self._make_request(
               ^^^^^^^^^^^^^^^^^^^
  File "/usr/local/miniconda3/envs/vValidator/lib/python3.12/site-packages/urllib3/connectionpool.py", line 491, in _make_request
    raise new_e
  File "/usr/local/miniconda3/envs/vValidator/lib/python3.12/site-packages/urllib3/connectionpool.py", line 467, in _make_request
    self._validate_conn(conn)
  File "/usr/local/miniconda3/envs/vValidator/lib/python3.12/site-packages/urllib3/connectionpool.py", line 1096, in _validate_conn
    conn.connect()
  File "/usr/local/miniconda3/envs/vValidator/lib/python3.12/site-packages/urllib3/connection.py", line 611, in connect
    self.sock = sock = self._new_conn()
                       ^^^^^^^^^^^^^^^^
  File "/usr/local/miniconda3/envs/vValidator/lib/python3.12/site-packages/urllib3/connection.py", line 210, in _new_conn
    raise NameResolutionError(self.host, self, e) from e
urllib3.exceptions.NameResolutionError: <urllib3.connection.HTTPSConnection object at 0x7fd8ec7bf200>: Failed to resolve 'rest.variantvalidator.org' ([Errno -3] Temporary failure in name resolution)

The above exception was the direct cause of the following exception:

Traceback (most recent call last):
  File "/usr/local/miniconda3/envs/vValidator/lib/python3.12/site-packages/requests/adapters.py", line 486, in send
    resp = conn.urlopen(
           ^^^^^^^^^^^^^
  File "/usr/local/miniconda3/envs/vValidator/lib/python3.12/site-packages/urllib3/connectionpool.py", line 844, in urlopen
    retries = retries.increment(
              ^^^^^^^^^^^^^^^^^^
  File "/usr/local/miniconda3/envs/vValidator/lib/python3.12/site-packages/urllib3/util/retry.py", line 515, in increment
    raise MaxRetryError(_pool, url, reason) from reason  # type: ignore[arg-type]
    ^^^^^^^^^^^^^^^^^^^^^^^^^^^^^^^^^^^^^^^^^^^^^^^^^^^
urllib3.exceptions.MaxRetryError: HTTPSConnectionPool(host='rest.variantvalidator.org', port=443): Max retries exceeded with url: /VariantValidator/variantvalidator/GRCh37/NM_000088.3:c.589G%3ET/NM_000093.4 (Caused by NameResolutionError("<urllib3.connection.HTTPSConnection object at 0x7fd8ec7bf200>: Failed to resolve 'rest.variantvalidator.org' ([Errno -3] Temporary failure in name resolution)"))

During handling of the above exception, another exception occurred:

Traceback (most recent call last):
  File "/home/kenny/PycharmProjects/vValidator/rest_variantValidator/application/rest_api/endpoints/variantvalidator_endpoints.py", line 56, in get
    validation = requests.get(url)
                 ^^^^^^^^^^^^^^^^^
  File "/usr/local/miniconda3/envs/vValidator/lib/python3.12/site-packages/requests/api.py", line 73, in get
    return request("get", url, params=params, **kwargs)
           ^^^^^^^^^^^^^^^^^^^^^^^^^^^^^^^^^^^^^^^^^^^^
  File "/usr/local/miniconda3/envs/vValidator/lib/python3.12/site-packages/requests/api.py", line 59, in request
    return session.request(method=method, url=url, **kwargs)
           ^^^^^^^^^^^^^^^^^^^^^^^^^^^^^^^^^^^^^^^^^^^^^^^^^
  File "/usr/local/miniconda3/envs/vValidator/lib/python3.12/site-packages/requests/sessions.py", line 589, in request
    resp = self.send(prep, **send_kwargs)
           ^^^^^^^^^^^^^^^^^^^^^^^^^^^^^^
  File "/usr/local/miniconda3/envs/vValidator/lib/python3.12/site-packages/requests/sessions.py", line 703, in send
    r = adapter.send(request, **kwargs)
        ^^^^^^^^^^^^^^^^^^^^^^^^^^^^^^^
  File "/usr/local/miniconda3/envs/vValidator/lib/python3.12/site-packages/requests/adapters.py", line 519, in send
    raise ConnectionError(e, request=request)
requests.exceptions.ConnectionError: HTTPSConnectionPool(host='rest.variantvalidator.org', port=443): Max retries exceeded with url: /VariantValidator/variantvalidator/GRCh37/NM_000088.3:c.589G%3ET/NM_000093.4 (Caused by NameResolutionError("<urllib3.connection.HTTPSConnection object at 0x7fd8ec7bf200>: Failed to resolve 'rest.variantvalidator.org' ([Errno -3] Temporary failure in name resolution)"))

During handling of the above exception, another exception occurred:

Traceback (most recent call last):
  File "/usr/local/miniconda3/envs/vValidator/lib/python3.12/site-packages/flask_restx/api.py", line 669, in error_router
    return self.handle_error(e)
           ^^^^^^^^^^^^^^^^^^^^
  File "/usr/local/miniconda3/envs/vValidator/lib/python3.12/site-packages/flask/app.py", line 867, in full_dispatch_request
    rv = self.dispatch_request()
         ^^^^^^^^^^^^^^^^^^^^^^^
  File "/usr/local/miniconda3/envs/vValidator/lib/python3.12/site-packages/flask/app.py", line 852, in dispatch_request
    return self.ensure_sync(self.view_functions[rule.endpoint])(**view_args)
           ^^^^^^^^^^^^^^^^^^^^^^^^^^^^^^^^^^^^^^^^^^^^^^^^^^^^^^^^^^^^^^^^^
  File "/usr/local/miniconda3/envs/vValidator/lib/python3.12/site-packages/flask_restx/api.py", line 402, in wrapper
    resp = resource(*args, **kwargs)
           ^^^^^^^^^^^^^^^^^^^^^^^^^
  File "/usr/local/miniconda3/envs/vValidator/lib/python3.12/site-packages/flask/views.py", line 109, in view
    return current_app.ensure_sync(self.dispatch_request)(**kwargs)
           ^^^^^^^^^^^^^^^^^^^^^^^^^^^^^^^^^^^^^^^^^^^^^^^^^^^^^^^^
  File "/usr/local/miniconda3/envs/vValidator/lib/python3.12/site-packages/flask_restx/resource.py", line 41, in dispatch_request
    resp = meth(*args, **kwargs)
           ^^^^^^^^^^^^^^^^^^^^^
  File "/home/kenny/PycharmProjects/vValidator/rest_variantValidator/application/rest_api/endpoints/variantvalidator_endpoints.py", line 58, in get
    raise exceptions.RemoteConnectionError('https://rest.variantvalidator.org//VariantValidator/variantvalidator currently '
utils.exceptions.RemoteConnectionError: https://rest.variantvalidator.org//VariantValidator/variantvalidator currently unavailable
